## 异常类型

# 异常类型都是内置类Throwable的子类

1. 1. Exception用于用户程序可能捕捉的异常情况。它也是你可以用来创建你自己用户异常类型子类的类

	2. 1. RuntimeException该类型的异常自动为你所编写的程序定义并且包括被零除和非法数组索引这样的错误。

	3. Error

- - 1. Error定义了在通常环境下不希望被程序捕获的异常。Error类型的异常用于Java运行时系统来显示与运行时系统本身有关的错误。堆栈溢出是这种错误的一例。本章将不讨论关于Error类型的异常处理，因为它们通常是灾难性的致命错误，不是你的程序可以控制的。

![img](C:/Users/26968/AppData/Local/YNote/data/qq88C60C557209F0740BC349C0ACE97ED4/0b5d69b8558d4925aee39f3098c8d03a/c887bccaa4b144622c82685097908f3d.png)

**try catch**

```java
import static java.lang.System.*;

public class Demo {
    public static void main(String[] args) {
        try {
            int d = 0;
            int a = 42 / d;
        } catch (ArithmeticException e) {
            out.println("你除零了。。。");
        } catch (ArrayIndexOutOfBoundsException e) {
            System.out.println("Array index oob: " + e);
        }
    }
}
```



**参数e表示正常错误时反应的信息**

java.lang.ArithmeticException: / by zero	（除0错误的e）

当你用多catch语句时，记住异常子类必须在它们任何父类之前使用是很重要的。这是因为运用父类的catch语句将捕获该类型及其所有子类类型的异常。这样，如果子类在父类后面，子类将永远不会到达。而且，Java中不能到达的代码是一个错误

**eg:**

```java
import static java.lang.System.*;

public class Demo {
    public static void main(String[] args) {
        try {
            int d = 0;
            int a = 42 / d;
        } catch (Exception e) {
            out.println("永远也不会抛出正确异常，优先抛出父类异常")
        } catch (ArithmeticException e) {
            out.println("你除零了。。。");
        }
    }
} 
```



**try语句嵌套**

```java
class NestTry {
    public static void main(String args[]) {
        try {
            int a = args.length;
            int b = 42 / a;
            System.out.println("a = " + a);
            try {
                if (a == 1)
                    a = a / (a - a);
                if (a == 2) {
                    int c[] = {1};
                    c[42] = 99; 
                }
            } catch (ArrayIndexOutOfBoundsException e) {
                System.out.println("Array index out-of-bounds: " + e);
            }
        } catch (ArithmeticException e) {
            System.out.println("Divide by 0: " + e);
        }
    }
}
```



程序执行在throw语句之后立即停止；后面的任何语句不被执行

主动抛出异常对象

class ThrowDemo {    static void demoproc() {        try {            throw new NullPointerException("demo");            //构建标准异常        } catch(NullPointerException e) {            System.out.println("Caught inside demoproc.");            throw e; // rethrow the exception        }    }     public static void main(String args[]) {        try {            demoproc();        } catch(NullPointerException e) {            System.out.println("Recaught: " + e);        }    } } 

**throws**

**方法可能抛出异常的声明**

语法：[(修饰符)](返回值类型)(方法名)([参数列表])[throws(异常类)]{......}

class ThrowsDemo {   static void throwOne() throws IllegalAccessException {     System.out.println("Inside throwOne.");     throw new IllegalAccessException("demo");   }   public static void main(String args[]) {     try {       throwOne();     } catch (IllegalAccessException e) {       System.out.println("Caught " + e);     }   } } 

**finally**

**无论有没有异常都会执行**

finally创建一个代码块。该代码块在一个try/catch 块完成之后另一个try/catch出现之前执行。finally块无论有没有异常抛出都会执行。

注意：如果finally块与一个try联合使用，finally块将在try结束之前执行。

**Java中内置异常**

**java.lang中定义的未检查异常子类**

| 异常                           | 说明                               |
| ------------------------------ | ---------------------------------- |
| ArithmeticException            | 算术错误，如被0除                  |
| ArrayIndexOutOfBoundsException | 数组下标出界                       |
| ArrayStoreException            | 数组元素赋值类型不兼容             |
| ClassCastException             | 非法强制转换类型                   |
| IllegalArgumentException       | 调用方法的参数非法                 |
| IllegalMonitorStateException   | 非法监控操作，如等待一个未锁定线程 |
| IllegalStateException          | 环境或应用状态不正确               |
| IllegalThreadStateException    | 请求操作与当前线程状态不兼容       |
| IndexOutOfBoundsException      | 某些类型索引越界                   |
| NullPointerException           | 非法使用空引用                     |
| NumberFormatException          | 字符串到数字格式非法转换           |
| SecurityException              | 试图违反安全性                     |
| StringIndexOutOfBounds         | 试图在字符串边界之外索引           |
| UnsupportedOperationException  | 遇到不支持的操作                   |

**java.lang中定义的检查异常**

| 异常                       | 意义                                    |
| -------------------------- | --------------------------------------- |
| ClassNotFoundException     | 找不到类                                |
| CloneNotSupportedException | 试图克隆一个不能实现Cloneable接口的对象 |
| IllegalAccessException     | 对一个类的访问被拒绝                    |
| InstantiationException     | 试图创建一个抽象类或者抽象接口的对象    |
| InterruptedException       | 一个线程被另一个线程中断                |
| NoSuchFieldException       | 请求的字段不存在                        |
| NoSuchMethodException      | 请求的方法不存在                        |

**Throwable定义的方法**

| 方法                                    | 描述                                                         |
| --------------------------------------- | ------------------------------------------------------------ |
| Throwable fillInStackTrace( )           | 返回一个包含完整堆栈轨迹的Throwable对象，该对象可能被再次引发。 |
| String getLocalizedMessage( )           | 返回一个异常的局部描述                                       |
| String getMessage( )                    | 返回一个异常的描述                                           |
| void printStackTrace( )                 | 显示堆栈轨迹                                                 |
| void printStackTrace(PrintStreamstream) | 把堆栈轨迹送到指定的流                                       |
| void printStackTrace(PrintWriterstream) | 把堆栈轨迹送到指定的流                                       |
| String toString( )                      | 返回一个包含异常描述的String对象。当输出一个Throwable对象时，该方法被println( )调用 |

**自建异常子类**

class MyException extends Exception {    //继承Exception    private int detail;    MyException(int a) {        detail = a;    }     public String toString() {        return "MyException[" + detail + "]";    } } class ExceptionDemo {    //产生错误的方法    static void compute(int a) throws MyException {        //必须声明自定义异常        System.out.println("Called compute(" + a + ")");        if(a > 10)            throw new MyException(a);        System.out.println("Normal exit");    }     public static void main(String args[]) {        try {            compute(1);            compute(20);        } catch (MyException e) {            System.out.println("Caught " + e);        }    } } 

**没有throws MyException**

![img](C:/Users/26968/AppData/Local/YNote/data/qq88C60C557209F0740BC349C0ACE97ED4/16c250f0669848f5b35bf44807a5c7fa/temp.png)

**断言**

**用于证明和测试程序的假设**

**断言可以再程序运行时删除，所以对代码的运行速度完全没有影响**

**断言的使用**

- assert<<布尔表达式>>;
- assert<<布尔表达式>>:<<细节描述>>

**如果表达式的值为false，将抛出AssertionError异常；**